2025-08-01 20:51:25,567 INFO    MainThread:440416 [wandb_setup.py:_flush():77] Current SDK version is 0.18.1
2025-08-01 20:51:25,568 INFO    MainThread:440416 [wandb_setup.py:_flush():77] Configure stats pid to 440416
2025-08-01 20:51:25,568 INFO    MainThread:440416 [wandb_setup.py:_flush():77] Loading settings from /work/home/maben/.config/wandb/settings
2025-08-01 20:51:25,568 INFO    MainThread:440416 [wandb_setup.py:_flush():77] Loading settings from /work/home/maben/project/blue_whale_lab/projects/pareto_ebm/project/scripts/wandb/settings
2025-08-01 20:51:25,568 INFO    MainThread:440416 [wandb_setup.py:_flush():77] Loading settings from environment variables: {}
2025-08-01 20:51:25,568 INFO    MainThread:440416 [wandb_setup.py:_flush():77] Applying setup settings: {'mode': None, '_disable_service': None}
2025-08-01 20:51:25,568 INFO    MainThread:440416 [wandb_setup.py:_flush():77] Inferring run settings from compute environment: {'program_relpath': 'jem_lightning_trainer.py', 'program_abspath': '/work/home/maben/project/blue_whale_lab/projects/pareto_ebm/project/scripts/jem_lightning_trainer.py', 'program': '/work/home/maben/project/blue_whale_lab/projects/pareto_ebm/project/scripts/jem_lightning_trainer.py'}
2025-08-01 20:51:25,568 INFO    MainThread:440416 [wandb_setup.py:_flush():77] Applying login settings: {}
2025-08-01 20:51:25,568 INFO    MainThread:440416 [wandb_init.py:_log_setup():532] Logging user logs to /work/home/maben/project/blue_whale_lab/projects/pareto_ebm/project/scripts/wandb/run-20250801_205125-h8e52dg7/logs/debug.log
2025-08-01 20:51:25,569 INFO    MainThread:440416 [wandb_init.py:_log_setup():533] Logging internal logs to /work/home/maben/project/blue_whale_lab/projects/pareto_ebm/project/scripts/wandb/run-20250801_205125-h8e52dg7/logs/debug-internal.log
2025-08-01 20:51:25,569 INFO    MainThread:440416 [wandb_init.py:init():616] calling init triggers
2025-08-01 20:51:25,569 INFO    MainThread:440416 [wandb_init.py:init():623] wandb.init called with sweep_config: {}
config: {'max_epochs': 10, 'batch_size': 64, 'lr': 0.0001, 'alpha': 0.1, 'hidden_features': 32, 'use_gpu': True, 'model_type': 'JEM', 'dataset': 'MNIST', 'fid_num_samples': 500, 'fid_batch_size': 50}
2025-08-01 20:51:25,569 INFO    MainThread:440416 [wandb_init.py:init():666] starting backend
2025-08-01 20:51:25,569 INFO    MainThread:440416 [wandb_init.py:init():670] setting up manager
2025-08-01 20:51:25,571 INFO    MainThread:440416 [backend.py:_multiprocessing_setup():105] multiprocessing start_methods=fork,spawn,forkserver, using: spawn
2025-08-01 20:51:25,573 INFO    MainThread:440416 [wandb_init.py:init():678] backend started and connected
2025-08-01 20:51:25,577 INFO    MainThread:440416 [wandb_init.py:init():773] updated telemetry
2025-08-01 20:51:25,579 INFO    MainThread:440416 [wandb_init.py:init():806] communicating run to backend with 90.0 second timeout
2025-08-01 20:52:39,178 INFO    Thread-1 (wrapped_target):440416 [retry.py:__call__():172] Retry attempt failed:
Traceback (most recent call last):
  File "/work/home/maben/software/anaconda3/envs/cf-design/lib/python3.10/site-packages/urllib3/connection.py", line 199, in _new_conn
    sock = connection.create_connection(
  File "/work/home/maben/software/anaconda3/envs/cf-design/lib/python3.10/site-packages/urllib3/util/connection.py", line 85, in create_connection
    raise err
  File "/work/home/maben/software/anaconda3/envs/cf-design/lib/python3.10/site-packages/urllib3/util/connection.py", line 73, in create_connection
    sock.connect(sa)
TimeoutError: timed out

The above exception was the direct cause of the following exception:

Traceback (most recent call last):
  File "/work/home/maben/software/anaconda3/envs/cf-design/lib/python3.10/site-packages/urllib3/connectionpool.py", line 789, in urlopen
    response = self._make_request(
  File "/work/home/maben/software/anaconda3/envs/cf-design/lib/python3.10/site-packages/urllib3/connectionpool.py", line 490, in _make_request
    raise new_e
  File "/work/home/maben/software/anaconda3/envs/cf-design/lib/python3.10/site-packages/urllib3/connectionpool.py", line 466, in _make_request
    self._validate_conn(conn)
  File "/work/home/maben/software/anaconda3/envs/cf-design/lib/python3.10/site-packages/urllib3/connectionpool.py", line 1095, in _validate_conn
    conn.connect()
  File "/work/home/maben/software/anaconda3/envs/cf-design/lib/python3.10/site-packages/urllib3/connection.py", line 693, in connect
    self.sock = sock = self._new_conn()
  File "/work/home/maben/software/anaconda3/envs/cf-design/lib/python3.10/site-packages/urllib3/connection.py", line 208, in _new_conn
    raise ConnectTimeoutError(
urllib3.exceptions.ConnectTimeoutError: (<urllib3.connection.HTTPSConnection object at 0x7fc776246530>, 'Connection to api.wandb.ai timed out. (connect timeout=20)')

The above exception was the direct cause of the following exception:

Traceback (most recent call last):
  File "/work/home/maben/software/anaconda3/envs/cf-design/lib/python3.10/site-packages/requests/adapters.py", line 667, in send
    resp = conn.urlopen(
  File "/work/home/maben/software/anaconda3/envs/cf-design/lib/python3.10/site-packages/urllib3/connectionpool.py", line 843, in urlopen
    retries = retries.increment(
  File "/work/home/maben/software/anaconda3/envs/cf-design/lib/python3.10/site-packages/urllib3/util/retry.py", line 519, in increment
    raise MaxRetryError(_pool, url, reason) from reason  # type: ignore[arg-type]
urllib3.exceptions.MaxRetryError: HTTPSConnectionPool(host='api.wandb.ai', port=443): Max retries exceeded with url: /graphql (Caused by ConnectTimeoutError(<urllib3.connection.HTTPSConnection object at 0x7fc776246530>, 'Connection to api.wandb.ai timed out. (connect timeout=20)'))

During handling of the above exception, another exception occurred:

Traceback (most recent call last):
  File "/work/home/maben/software/anaconda3/envs/cf-design/lib/python3.10/site-packages/wandb/sdk/lib/retry.py", line 131, in __call__
    result = self._call_fn(*args, **kwargs)
  File "/work/home/maben/software/anaconda3/envs/cf-design/lib/python3.10/site-packages/wandb/sdk/internal/internal_api.py", line 345, in execute
    return self.client.execute(*args, **kwargs)  # type: ignore
  File "/work/home/maben/software/anaconda3/envs/cf-design/lib/python3.10/site-packages/wandb/vendor/gql-0.2.0/wandb_gql/client.py", line 52, in execute
    result = self._get_result(document, *args, **kwargs)
  File "/work/home/maben/software/anaconda3/envs/cf-design/lib/python3.10/site-packages/wandb/vendor/gql-0.2.0/wandb_gql/client.py", line 60, in _get_result
    return self.transport.execute(document, *args, **kwargs)
  File "/work/home/maben/software/anaconda3/envs/cf-design/lib/python3.10/site-packages/wandb/sdk/lib/gql_request.py", line 58, in execute
    request = self.session.post(self.url, **post_args)
  File "/work/home/maben/software/anaconda3/envs/cf-design/lib/python3.10/site-packages/requests/sessions.py", line 637, in post
    return self.request("POST", url, data=data, json=json, **kwargs)
  File "/work/home/maben/software/anaconda3/envs/cf-design/lib/python3.10/site-packages/requests/sessions.py", line 589, in request
    resp = self.send(prep, **send_kwargs)
  File "/work/home/maben/software/anaconda3/envs/cf-design/lib/python3.10/site-packages/requests/sessions.py", line 703, in send
    r = adapter.send(request, **kwargs)
  File "/work/home/maben/software/anaconda3/envs/cf-design/lib/python3.10/site-packages/requests/adapters.py", line 688, in send
    raise ConnectTimeout(e, request=request)
requests.exceptions.ConnectTimeout: HTTPSConnectionPool(host='api.wandb.ai', port=443): Max retries exceeded with url: /graphql (Caused by ConnectTimeoutError(<urllib3.connection.HTTPSConnection object at 0x7fc776246530>, 'Connection to api.wandb.ai timed out. (connect timeout=20)'))
2025-08-01 20:52:55,710 ERROR   MainThread:440416 [wandb_init.py:init():832] encountered error: Run initialization has timed out after 90.0 sec. 
Please refer to the documentation for additional information: https://docs.wandb.ai/guides/track/tracking-faq#initstarterror-error-communicating-with-wandb-process-
2025-08-01 20:52:55,710 ERROR   MainThread:440416 [wandb_init.py:init():1251] error in wandb.init()
Traceback (most recent call last):
  File "/work/home/maben/software/anaconda3/envs/cf-design/lib/python3.10/site-packages/wandb/sdk/wandb_init.py", line 1241, in init
    return wi.init()
  File "/work/home/maben/software/anaconda3/envs/cf-design/lib/python3.10/site-packages/wandb/sdk/wandb_init.py", line 838, in init
    raise error
wandb.errors.CommError: Run initialization has timed out after 90.0 sec. 
Please refer to the documentation for additional information: https://docs.wandb.ai/guides/track/tracking-faq#initstarterror-error-communicating-with-wandb-process-
2025-08-01 20:52:57,733 WARNING MsgRouterThr:440416 [router.py:message_loop():77] message_loop has been closed
