2025-08-01 21:01:43,562 INFO    MainThread:442045 [wandb_setup.py:_flush():76] Loading settings from /work/home/maben/.config/wandb/settings
2025-08-01 21:01:43,562 INFO    MainThread:442045 [wandb_setup.py:_flush():76] Loading settings from /work/home/maben/project/blue_whale_lab/projects/pareto_ebm/project/scripts/wandb/settings
2025-08-01 21:01:43,562 INFO    MainThread:442045 [wandb_setup.py:_flush():76] Loading settings from environment variables: {}
2025-08-01 21:01:43,562 INFO    MainThread:442045 [wandb_setup.py:_flush():76] Inferring run settings from compute environment: {'program_relpath': 'jem_lightning_trainer.py', 'program': '/work/home/maben/project/blue_whale_lab/projects/pareto_ebm/project/scripts/jem_lightning_trainer.py'}
2025-08-01 21:01:43,562 INFO    MainThread:442045 [wandb_init.py:_log_setup():428] Logging user logs to /work/home/maben/project/blue_whale_lab/projects/pareto_ebm/project/scripts/wandb/run-20250801_210143-xxuotzp9/logs/debug.log
2025-08-01 21:01:43,563 INFO    MainThread:442045 [wandb_init.py:_log_setup():429] Logging internal logs to /work/home/maben/project/blue_whale_lab/projects/pareto_ebm/project/scripts/wandb/run-20250801_210143-xxuotzp9/logs/debug-internal.log
2025-08-01 21:01:43,563 INFO    MainThread:442045 [wandb_init.py:init():462] calling init triggers
2025-08-01 21:01:43,563 INFO    MainThread:442045 [wandb_init.py:init():465] wandb.init called with sweep_config: {}
config: {'max_epochs': 10, 'batch_size': 64, 'lr': 0.0001, 'alpha': 0.1, 'hidden_features': 32, 'use_gpu': True, 'model_type': 'JEM', 'dataset': 'MNIST', 'fid_num_samples': 500, 'fid_batch_size': 50}
2025-08-01 21:01:43,563 INFO    MainThread:442045 [wandb_init.py:init():515] starting backend
2025-08-01 21:01:43,563 INFO    MainThread:442045 [backend.py:_multiprocessing_setup():97] multiprocessing start_methods=fork,spawn,forkserver, using: spawn
2025-08-01 21:01:43,570 INFO    MainThread:442045 [backend.py:ensure_launched():217] starting backend process...
2025-08-01 21:01:43,572 INFO    MainThread:442045 [backend.py:ensure_launched():222] started backend process with pid: 442155
2025-08-01 21:01:43,573 INFO    MainThread:442045 [wandb_init.py:init():525] backend started and connected
2025-08-01 21:01:43,574 INFO    MainThread:442045 [wandb_init.py:init():596] updated telemetry
2025-08-01 21:01:43,576 INFO    MainThread:442045 [wandb_init.py:init():627] communicating run to backend with 30 second timeout
2025-08-01 21:02:11,957 ERROR   Thread-1 (wrapped_target):442045 [retry.py:__call__():126] Retry attempt failed:
Traceback (most recent call last):
  File "/work/home/maben/software/anaconda3/envs/cf-design/lib/python3.10/site-packages/urllib3/connection.py", line 199, in _new_conn
    sock = connection.create_connection(
  File "/work/home/maben/software/anaconda3/envs/cf-design/lib/python3.10/site-packages/urllib3/util/connection.py", line 85, in create_connection
    raise err
  File "/work/home/maben/software/anaconda3/envs/cf-design/lib/python3.10/site-packages/urllib3/util/connection.py", line 73, in create_connection
    sock.connect(sa)
TimeoutError: timed out

The above exception was the direct cause of the following exception:

Traceback (most recent call last):
  File "/work/home/maben/software/anaconda3/envs/cf-design/lib/python3.10/site-packages/urllib3/connectionpool.py", line 775, in urlopen
    self._prepare_proxy(conn)
  File "/work/home/maben/software/anaconda3/envs/cf-design/lib/python3.10/site-packages/urllib3/connectionpool.py", line 1044, in _prepare_proxy
    conn.connect()
  File "/work/home/maben/software/anaconda3/envs/cf-design/lib/python3.10/site-packages/urllib3/connection.py", line 693, in connect
    self.sock = sock = self._new_conn()
  File "/work/home/maben/software/anaconda3/envs/cf-design/lib/python3.10/site-packages/urllib3/connection.py", line 208, in _new_conn
    raise ConnectTimeoutError(
urllib3.exceptions.ConnectTimeoutError: (<urllib3.connection.HTTPSConnection object at 0x7f7f9ea068f0>, 'Connection to 192.168.137.80 timed out. (connect timeout=10)')

The above exception was the direct cause of the following exception:

urllib3.exceptions.ProxyError: ('Unable to connect to proxy', ConnectTimeoutError(<urllib3.connection.HTTPSConnection object at 0x7f7f9ea068f0>, 'Connection to 192.168.137.80 timed out. (connect timeout=10)'))

The above exception was the direct cause of the following exception:

Traceback (most recent call last):
  File "/work/home/maben/software/anaconda3/envs/cf-design/lib/python3.10/site-packages/requests/adapters.py", line 667, in send
    resp = conn.urlopen(
  File "/work/home/maben/software/anaconda3/envs/cf-design/lib/python3.10/site-packages/urllib3/connectionpool.py", line 843, in urlopen
    retries = retries.increment(
  File "/work/home/maben/software/anaconda3/envs/cf-design/lib/python3.10/site-packages/urllib3/util/retry.py", line 519, in increment
    raise MaxRetryError(_pool, url, reason) from reason  # type: ignore[arg-type]
urllib3.exceptions.MaxRetryError: HTTPSConnectionPool(host='api.wandb.ai', port=443): Max retries exceeded with url: /graphql (Caused by ProxyError('Unable to connect to proxy', ConnectTimeoutError(<urllib3.connection.HTTPSConnection object at 0x7f7f9ea068f0>, 'Connection to 192.168.137.80 timed out. (connect timeout=10)')))

During handling of the above exception, another exception occurred:

Traceback (most recent call last):
  File "/work/home/maben/software/anaconda3/envs/cf-design/lib/python3.10/site-packages/wandb/sdk/lib/retry.py", line 102, in __call__
    result = self._call_fn(*args, **kwargs)
  File "/work/home/maben/software/anaconda3/envs/cf-design/lib/python3.10/site-packages/wandb/sdk/internal/internal_api.py", line 140, in execute
    return self.client.execute(*args, **kwargs)
  File "/work/home/maben/software/anaconda3/envs/cf-design/lib/python3.10/site-packages/wandb/vendor/gql-0.2.0/wandb_gql/client.py", line 52, in execute
    result = self._get_result(document, *args, **kwargs)
  File "/work/home/maben/software/anaconda3/envs/cf-design/lib/python3.10/site-packages/wandb/vendor/gql-0.2.0/wandb_gql/client.py", line 60, in _get_result
    return self.transport.execute(document, *args, **kwargs)
  File "/work/home/maben/software/anaconda3/envs/cf-design/lib/python3.10/site-packages/wandb/vendor/gql-0.2.0/wandb_gql/transport/requests.py", line 38, in execute
    request = requests.post(self.url, **post_args)
  File "/work/home/maben/software/anaconda3/envs/cf-design/lib/python3.10/site-packages/requests/api.py", line 115, in post
    return request("post", url, data=data, json=json, **kwargs)
  File "/work/home/maben/software/anaconda3/envs/cf-design/lib/python3.10/site-packages/requests/api.py", line 59, in request
    return session.request(method=method, url=url, **kwargs)
  File "/work/home/maben/software/anaconda3/envs/cf-design/lib/python3.10/site-packages/requests/sessions.py", line 589, in request
    resp = self.send(prep, **send_kwargs)
  File "/work/home/maben/software/anaconda3/envs/cf-design/lib/python3.10/site-packages/requests/sessions.py", line 703, in send
    r = adapter.send(request, **kwargs)
  File "/work/home/maben/software/anaconda3/envs/cf-design/lib/python3.10/site-packages/requests/adapters.py", line 694, in send
    raise ProxyError(e, request=request)
requests.exceptions.ProxyError: HTTPSConnectionPool(host='api.wandb.ai', port=443): Max retries exceeded with url: /graphql (Caused by ProxyError('Unable to connect to proxy', ConnectTimeoutError(<urllib3.connection.HTTPSConnection object at 0x7f7f9ea068f0>, 'Connection to 192.168.137.80 timed out. (connect timeout=10)')))
2025-08-01 21:02:13,577 INFO    MainThread:442045 [interface_shared.py:_communicate_run():326] couldn't get run from backend
2025-08-01 21:02:13,577 ERROR   MainThread:442045 [wandb_init.py:init():636] backend process timed out
2025-08-01 21:02:13,577 ERROR   MainThread:442045 [wandb_init.py:init():647] encountered error: Error communicating with wandb process
try: wandb.init(settings=wandb.Settings(start_method='fork'))
or:  wandb.init(settings=wandb.Settings(start_method='thread'))
For more info see: https://docs.wandb.ai/library/init#init-start-error
